<?xml version="1.0" ?>
<robot name="Assignent" xmlns:xacro="http://www.ros.org/wiki/xacro">

<xacro:include filename="$(find Assignent_description)/urdf/materials.xacro" />
<xacro:include filename="$(find Assignent_description)/urdf/Assignent.trans" />
<xacro:include filename="$(find Assignent_description)/urdf/Assignent.gazebo" />
<link name="base_link">
  <inertial>
    <origin xyz="-0.008616682743921076 -9.376906117987113e-08 0.000239113764492349" rpy="0 0 0"/>
    <mass value="7.430343276716578e-05"/>
    <inertia ixx="0.0" iyy="0.0" izz="0.0" ixy="0.0" iyz="-0.0" ixz="0.0"/>
  </inertial>
  <visual>
    <origin xyz="0 0 0" rpy="0 0 0"/>
    <geometry>
      <mesh filename="package://Assignent_description/meshes/base_link.stl" scale="0.001 0.001 0.001"/>
    </geometry>
    <material name="silver"/>
  </visual>
  <collision>
    <origin xyz="0 0 0" rpy="0 0 0"/>
    <geometry>
      <mesh filename="package://Assignent_description/meshes/base_link.stl" scale="0.001 0.001 0.001"/>
    </geometry>
  </collision>
</link>

<link name="right__wheel_1">
  <inertial>
    <origin xyz="-1.8693918803561194e-07 -0.0005000001404732298 5.421010862427522e-20" rpy="0 0 0"/>
    <mass value="8.1045181875344e-06"/>
    <inertia ixx="0.0" iyy="0.0" izz="0.0" ixy="0.0" iyz="0.0" ixz="-0.0"/>
  </inertial>
  <visual>
    <origin xyz="0.016469 0.006 -0.0002" rpy="0 0 0"/>
    <geometry>
      <mesh filename="package://Assignent_description/meshes/right__wheel_1.stl" scale="0.001 0.001 0.001"/>
    </geometry>
    <material name="silver"/>
  </visual>
  <collision>
    <origin xyz="0.016469 0.006 -0.0002" rpy="0 0 0"/>
    <geometry>
      <mesh filename="package://Assignent_description/meshes/right__wheel_1.stl" scale="0.001 0.001 0.001"/>
    </geometry>
  </collision>
</link>

<link name="left_wheel_1">
  <inertial>
    <origin xyz="-1.8677630713240245e-07 0.0005000000894069675 1.3552527156068805e-19" rpy="0 0 0"/>
    <mass value="8.165801257993449e-06"/>
    <inertia ixx="0.0" iyy="0.0" izz="0.0" ixy="0.0" iyz="0.0" ixz="-0.0"/>
  </inertial>
  <visual>
    <origin xyz="0.016469 -0.006 -0.0002" rpy="0 0 0"/>
    <geometry>
      <mesh filename="package://Assignent_description/meshes/left_wheel_1.stl" scale="0.001 0.001 0.001"/>
    </geometry>
    <material name="silver"/>
  </visual>
  <collision>
    <origin xyz="0.016469 -0.006 -0.0002" rpy="0 0 0"/>
    <geometry>
      <mesh filename="package://Assignent_description/meshes/left_wheel_1.stl" scale="0.001 0.001 0.001"/>
    </geometry>
  </collision>
</link>

<joint name="Revolute 1" type="continuous">
  <origin xyz="-0.016469 -0.006 0.0002" rpy="0 0 0"/>
  <parent link="base_link"/>
  <child link="right__wheel_1"/>
  <axis xyz="-0.0 -1.0 0.0"/>
</joint>

<joint name="Revolute 2" type="continuous">
  <origin xyz="-0.016469 0.006 0.0002" rpy="0 0 0"/>
  <parent link="base_link"/>
  <child link="left_wheel_1"/>
  <axis xyz="0.0 1.0 0.0"/>
</joint>

</robot>
